Watching for file changes with StatReloader
[13/Nov/2020 12:35:45] "OPTIONS /api/django/summary/qna/ HTTP/1.0" 200 0
[13/Nov/2020 12:35:47] "POST /api/django/summary/qna/ HTTP/1.0" 200 1528
/home/ubuntu/s03p31b108/backend/django/summary/views.py changed, reloading.
Performing system checks...

System check identified no issues (0 silenced).
November 13, 2020 - 12:28:13
Django version 2.2, using settings 'API.settings'
Starting development server at http://127.0.0.1:8000/
Quit the server with CONTROL-C.
Watching for file changes with StatReloader
Watching for file changes with StatReloader
[13/Nov/2020 13:23:21] "OPTIONS /api/django/summary/extract/ HTTP/1.0" 200 0
[13/Nov/2020 13:25:04] "POST /api/django/summary/extract/ HTTP/1.0" 200 3
Watching for file changes with StatReloader
[13/Nov/2020 17:05:27] "POST /api/django/summary/qna/ HTTP/1.0" 200 2472
[13/Nov/2020 17:05:58] "POST /api/django/summary/qna/ HTTP/1.0" 200 2472
[13/Nov/2020 17:10:38] "POST /api/django/summary/qna/ HTTP/1.0" 200 2472
[13/Nov/2020 17:15:01] "OPTIONS /api/django/summary/qna/ HTTP/1.0" 200 0
[13/Nov/2020 17:15:02] "POST /api/django/summary/qna/ HTTP/1.0" 200 20
[13/Nov/2020 17:15:09] "OPTIONS /api/django/summary/qna/ HTTP/1.0" 200 0
[13/Nov/2020 17:15:11] "POST /api/django/summary/qna/ HTTP/1.0" 200 2472
[13/Nov/2020 17:17:12] "OPTIONS /api/django/summary/qna/ HTTP/1.0" 200 0
[13/Nov/2020 17:17:14] "POST /api/django/summary/qna/ HTTP/1.0" 200 2472
[13/Nov/2020 17:24:38] "POST /api/django/summary/qna/ HTTP/1.0" 200 4612
[13/Nov/2020 17:44:45] "POST /api/django/summary/qna/ HTTP/1.0" 200 2472
[13/Nov/2020 17:46:41] "POST /api/django/summary/qna/ HTTP/1.0" 200 2472
[13/Nov/2020 17:47:28] "OPTIONS /api/django/summary/qna/ HTTP/1.0" 200 0
[13/Nov/2020 17:47:30] "POST /api/django/summary/qna/ HTTP/1.0" 200 2472
[13/Nov/2020 19:54:56] "POST /api/django/summary/qna/ HTTP/1.0" 200 44
Internal Server Error: /api/django/summary/extract/
Traceback (most recent call last):
  File "/home/ubuntu/s03p31b108/backend/django/venv/lib/python3.6/site-packages/django/core/handlers/exception.py", line 34, in inner
    response = get_response(request)
  File "/home/ubuntu/s03p31b108/backend/django/venv/lib/python3.6/site-packages/django/core/handlers/base.py", line 115, in _get_response
    response = self.process_exception_by_middleware(e, request)
  File "/home/ubuntu/s03p31b108/backend/django/venv/lib/python3.6/site-packages/django/core/handlers/base.py", line 113, in _get_response
    response = wrapped_callback(request, *callback_args, **callback_kwargs)
  File "/home/ubuntu/s03p31b108/backend/django/venv/lib/python3.6/site-packages/django/views/decorators/csrf.py", line 54, in wrapped_view
    return view_func(*args, **kwargs)
  File "/home/ubuntu/s03p31b108/backend/django/venv/lib/python3.6/site-packages/django/views/generic/base.py", line 71, in view
    return self.dispatch(request, *args, **kwargs)
  File "/home/ubuntu/s03p31b108/backend/django/venv/lib/python3.6/site-packages/rest_framework/views.py", line 509, in dispatch
    response = self.handle_exception(exc)
  File "/home/ubuntu/s03p31b108/backend/django/venv/lib/python3.6/site-packages/rest_framework/views.py", line 469, in handle_exception
    self.raise_uncaught_exception(exc)
  File "/home/ubuntu/s03p31b108/backend/django/venv/lib/python3.6/site-packages/rest_framework/views.py", line 480, in raise_uncaught_exception
    raise exc
  File "/home/ubuntu/s03p31b108/backend/django/venv/lib/python3.6/site-packages/rest_framework/views.py", line 506, in dispatch
    response = handler(request, *args, **kwargs)
  File "/home/ubuntu/s03p31b108/backend/django/venv/lib/python3.6/site-packages/rest_framework/decorators.py", line 50, in handler
    return func(*args, **kwargs)
  File "/home/ubuntu/s03p31b108/backend/django/summary/views.py", line 137, in extract_image
    video = Video.objects.get(video_id=video_id)
  File "/home/ubuntu/s03p31b108/backend/django/venv/lib/python3.6/site-packages/django/db/models/manager.py", line 82, in manager_method
    return getattr(self.get_queryset(), name)(*args, **kwargs)
  File "/home/ubuntu/s03p31b108/backend/django/venv/lib/python3.6/site-packages/django/db/models/query.py", line 408, in get
    self.model._meta.object_name
summary.models.Video.DoesNotExist: Video matching query does not exist.
[13/Nov/2020 19:55:12] "POST /api/django/summary/extract/ HTTP/1.0" 500 16227
Internal Server Error: /api/django/summary/extract/
Traceback (most recent call last):
  File "/home/ubuntu/s03p31b108/backend/django/venv/lib/python3.6/site-packages/django/core/handlers/exception.py", line 34, in inner
    response = get_response(request)
  File "/home/ubuntu/s03p31b108/backend/django/venv/lib/python3.6/site-packages/django/core/handlers/base.py", line 115, in _get_response
    response = self.process_exception_by_middleware(e, request)
  File "/home/ubuntu/s03p31b108/backend/django/venv/lib/python3.6/site-packages/django/core/handlers/base.py", line 113, in _get_response
    response = wrapped_callback(request, *callback_args, **callback_kwargs)
  File "/home/ubuntu/s03p31b108/backend/django/venv/lib/python3.6/site-packages/django/views/decorators/csrf.py", line 54, in wrapped_view
    return view_func(*args, **kwargs)
  File "/home/ubuntu/s03p31b108/backend/django/venv/lib/python3.6/site-packages/django/views/generic/base.py", line 71, in view
    return self.dispatch(request, *args, **kwargs)
  File "/home/ubuntu/s03p31b108/backend/django/venv/lib/python3.6/site-packages/rest_framework/views.py", line 509, in dispatch
    response = self.handle_exception(exc)
  File "/home/ubuntu/s03p31b108/backend/django/venv/lib/python3.6/site-packages/rest_framework/views.py", line 469, in handle_exception
    self.raise_uncaught_exception(exc)
  File "/home/ubuntu/s03p31b108/backend/django/venv/lib/python3.6/site-packages/rest_framework/views.py", line 480, in raise_uncaught_exception
    raise exc
  File "/home/ubuntu/s03p31b108/backend/django/venv/lib/python3.6/site-packages/rest_framework/views.py", line 506, in dispatch
    response = handler(request, *args, **kwargs)
  File "/home/ubuntu/s03p31b108/backend/django/venv/lib/python3.6/site-packages/rest_framework/decorators.py", line 50, in handler
    return func(*args, **kwargs)
  File "/home/ubuntu/s03p31b108/backend/django/summary/views.py", line 137, in extract_image
    video = Video.objects.get(video_id=video_id)
  File "/home/ubuntu/s03p31b108/backend/django/venv/lib/python3.6/site-packages/django/db/models/manager.py", line 82, in manager_method
    return getattr(self.get_queryset(), name)(*args, **kwargs)
  File "/home/ubuntu/s03p31b108/backend/django/venv/lib/python3.6/site-packages/django/db/models/query.py", line 408, in get
    self.model._meta.object_name
summary.models.Video.DoesNotExist: Video matching query does not exist.
[13/Nov/2020 19:57:06] "POST /api/django/summary/extract/ HTTP/1.0" 500 16227
Internal Server Error: /api/django/summary/extract/
Traceback (most recent call last):
  File "/home/ubuntu/s03p31b108/backend/django/venv/lib/python3.6/site-packages/django/core/handlers/exception.py", line 34, in inner
    response = get_response(request)
  File "/home/ubuntu/s03p31b108/backend/django/venv/lib/python3.6/site-packages/django/core/handlers/base.py", line 115, in _get_response
    response = self.process_exception_by_middleware(e, request)
  File "/home/ubuntu/s03p31b108/backend/django/venv/lib/python3.6/site-packages/django/core/handlers/base.py", line 113, in _get_response
    response = wrapped_callback(request, *callback_args, **callback_kwargs)
  File "/home/ubuntu/s03p31b108/backend/django/venv/lib/python3.6/site-packages/django/views/decorators/csrf.py", line 54, in wrapped_view
    return view_func(*args, **kwargs)
  File "/home/ubuntu/s03p31b108/backend/django/venv/lib/python3.6/site-packages/django/views/generic/base.py", line 71, in view
    return self.dispatch(request, *args, **kwargs)
  File "/home/ubuntu/s03p31b108/backend/django/venv/lib/python3.6/site-packages/rest_framework/views.py", line 509, in dispatch
    response = self.handle_exception(exc)
  File "/home/ubuntu/s03p31b108/backend/django/venv/lib/python3.6/site-packages/rest_framework/views.py", line 469, in handle_exception
    self.raise_uncaught_exception(exc)
  File "/home/ubuntu/s03p31b108/backend/django/venv/lib/python3.6/site-packages/rest_framework/views.py", line 480, in raise_uncaught_exception
    raise exc
  File "/home/ubuntu/s03p31b108/backend/django/venv/lib/python3.6/site-packages/rest_framework/views.py", line 506, in dispatch
    response = handler(request, *args, **kwargs)
  File "/home/ubuntu/s03p31b108/backend/django/venv/lib/python3.6/site-packages/rest_framework/decorators.py", line 50, in handler
    return func(*args, **kwargs)
  File "/home/ubuntu/s03p31b108/backend/django/summary/views.py", line 137, in extract_image
    video = Video.objects.get(video_id=video_id)
  File "/home/ubuntu/s03p31b108/backend/django/venv/lib/python3.6/site-packages/django/db/models/manager.py", line 82, in manager_method
    return getattr(self.get_queryset(), name)(*args, **kwargs)
  File "/home/ubuntu/s03p31b108/backend/django/venv/lib/python3.6/site-packages/django/db/models/query.py", line 408, in get
    self.model._meta.object_name
summary.models.Video.DoesNotExist: Video matching query does not exist.
[13/Nov/2020 19:57:59] "POST /api/django/summary/extract/ HTTP/1.0" 500 16227
Internal Server Error: /api/django/summary/extract/
Traceback (most recent call last):
  File "/home/ubuntu/s03p31b108/backend/django/venv/lib/python3.6/site-packages/django/core/handlers/exception.py", line 34, in inner
    response = get_response(request)
  File "/home/ubuntu/s03p31b108/backend/django/venv/lib/python3.6/site-packages/django/core/handlers/base.py", line 115, in _get_response
    response = self.process_exception_by_middleware(e, request)
  File "/home/ubuntu/s03p31b108/backend/django/venv/lib/python3.6/site-packages/django/core/handlers/base.py", line 113, in _get_response
    response = wrapped_callback(request, *callback_args, **callback_kwargs)
  File "/home/ubuntu/s03p31b108/backend/django/venv/lib/python3.6/site-packages/django/views/decorators/csrf.py", line 54, in wrapped_view
    return view_func(*args, **kwargs)
  File "/home/ubuntu/s03p31b108/backend/django/venv/lib/python3.6/site-packages/django/views/generic/base.py", line 71, in view
    return self.dispatch(request, *args, **kwargs)
  File "/home/ubuntu/s03p31b108/backend/django/venv/lib/python3.6/site-packages/rest_framework/views.py", line 509, in dispatch
    response = self.handle_exception(exc)
  File "/home/ubuntu/s03p31b108/backend/django/venv/lib/python3.6/site-packages/rest_framework/views.py", line 469, in handle_exception
    self.raise_uncaught_exception(exc)
  File "/home/ubuntu/s03p31b108/backend/django/venv/lib/python3.6/site-packages/rest_framework/views.py", line 480, in raise_uncaught_exception
    raise exc
  File "/home/ubuntu/s03p31b108/backend/django/venv/lib/python3.6/site-packages/rest_framework/views.py", line 506, in dispatch
    response = handler(request, *args, **kwargs)
  File "/home/ubuntu/s03p31b108/backend/django/venv/lib/python3.6/site-packages/rest_framework/decorators.py", line 50, in handler
    return func(*args, **kwargs)
  File "/home/ubuntu/s03p31b108/backend/django/summary/views.py", line 137, in extract_image
    video = Video.objects.get(video_id=video_id)
  File "/home/ubuntu/s03p31b108/backend/django/venv/lib/python3.6/site-packages/django/db/models/manager.py", line 82, in manager_method
    return getattr(self.get_queryset(), name)(*args, **kwargs)
  File "/home/ubuntu/s03p31b108/backend/django/venv/lib/python3.6/site-packages/django/db/models/query.py", line 408, in get
    self.model._meta.object_name
summary.models.Video.DoesNotExist: Video matching query does not exist.
[13/Nov/2020 19:58:20] "POST /api/django/summary/extract/ HTTP/1.0" 500 16227
Internal Server Error: /api/django/summary/extract/
Traceback (most recent call last):
  File "/home/ubuntu/s03p31b108/backend/django/venv/lib/python3.6/site-packages/django/core/handlers/exception.py", line 34, in inner
    response = get_response(request)
  File "/home/ubuntu/s03p31b108/backend/django/venv/lib/python3.6/site-packages/django/core/handlers/base.py", line 115, in _get_response
    response = self.process_exception_by_middleware(e, request)
  File "/home/ubuntu/s03p31b108/backend/django/venv/lib/python3.6/site-packages/django/core/handlers/base.py", line 113, in _get_response
    response = wrapped_callback(request, *callback_args, **callback_kwargs)
  File "/home/ubuntu/s03p31b108/backend/django/venv/lib/python3.6/site-packages/django/views/decorators/csrf.py", line 54, in wrapped_view
    return view_func(*args, **kwargs)
  File "/home/ubuntu/s03p31b108/backend/django/venv/lib/python3.6/site-packages/django/views/generic/base.py", line 71, in view
    return self.dispatch(request, *args, **kwargs)
  File "/home/ubuntu/s03p31b108/backend/django/venv/lib/python3.6/site-packages/rest_framework/views.py", line 509, in dispatch
    response = self.handle_exception(exc)
  File "/home/ubuntu/s03p31b108/backend/django/venv/lib/python3.6/site-packages/rest_framework/views.py", line 469, in handle_exception
    self.raise_uncaught_exception(exc)
  File "/home/ubuntu/s03p31b108/backend/django/venv/lib/python3.6/site-packages/rest_framework/views.py", line 480, in raise_uncaught_exception
    raise exc
  File "/home/ubuntu/s03p31b108/backend/django/venv/lib/python3.6/site-packages/rest_framework/views.py", line 506, in dispatch
    response = handler(request, *args, **kwargs)
  File "/home/ubuntu/s03p31b108/backend/django/venv/lib/python3.6/site-packages/rest_framework/decorators.py", line 50, in handler
    return func(*args, **kwargs)
  File "/home/ubuntu/s03p31b108/backend/django/summary/views.py", line 137, in extract_image
    video = Video.objects.get(video_id=video_id)
  File "/home/ubuntu/s03p31b108/backend/django/venv/lib/python3.6/site-packages/django/db/models/manager.py", line 82, in manager_method
    return getattr(self.get_queryset(), name)(*args, **kwargs)
  File "/home/ubuntu/s03p31b108/backend/django/venv/lib/python3.6/site-packages/django/db/models/query.py", line 408, in get
    self.model._meta.object_name
summary.models.Video.DoesNotExist: Video matching query does not exist.
[13/Nov/2020 19:58:43] "POST /api/django/summary/extract/ HTTP/1.0" 500 16227
Internal Server Error: /api/django/summary/extract/
Traceback (most recent call last):
  File "/home/ubuntu/s03p31b108/backend/django/venv/lib/python3.6/site-packages/django/core/handlers/exception.py", line 34, in inner
    response = get_response(request)
  File "/home/ubuntu/s03p31b108/backend/django/venv/lib/python3.6/site-packages/django/core/handlers/base.py", line 115, in _get_response
    response = self.process_exception_by_middleware(e, request)
  File "/home/ubuntu/s03p31b108/backend/django/venv/lib/python3.6/site-packages/django/core/handlers/base.py", line 113, in _get_response
    response = wrapped_callback(request, *callback_args, **callback_kwargs)
  File "/home/ubuntu/s03p31b108/backend/django/venv/lib/python3.6/site-packages/django/views/decorators/csrf.py", line 54, in wrapped_view
    return view_func(*args, **kwargs)
  File "/home/ubuntu/s03p31b108/backend/django/venv/lib/python3.6/site-packages/django/views/generic/base.py", line 71, in view
    return self.dispatch(request, *args, **kwargs)
  File "/home/ubuntu/s03p31b108/backend/django/venv/lib/python3.6/site-packages/rest_framework/views.py", line 509, in dispatch
    response = self.handle_exception(exc)
  File "/home/ubuntu/s03p31b108/backend/django/venv/lib/python3.6/site-packages/rest_framework/views.py", line 469, in handle_exception
    self.raise_uncaught_exception(exc)
  File "/home/ubuntu/s03p31b108/backend/django/venv/lib/python3.6/site-packages/rest_framework/views.py", line 480, in raise_uncaught_exception
    raise exc
  File "/home/ubuntu/s03p31b108/backend/django/venv/lib/python3.6/site-packages/rest_framework/views.py", line 506, in dispatch
    response = handler(request, *args, **kwargs)
  File "/home/ubuntu/s03p31b108/backend/django/venv/lib/python3.6/site-packages/rest_framework/decorators.py", line 50, in handler
    return func(*args, **kwargs)
  File "/home/ubuntu/s03p31b108/backend/django/summary/views.py", line 137, in extract_image
    video = Video.objects.get(video_id=video_id)
  File "/home/ubuntu/s03p31b108/backend/django/venv/lib/python3.6/site-packages/django/db/models/manager.py", line 82, in manager_method
    return getattr(self.get_queryset(), name)(*args, **kwargs)
  File "/home/ubuntu/s03p31b108/backend/django/venv/lib/python3.6/site-packages/django/db/models/query.py", line 408, in get
    self.model._meta.object_name
summary.models.Video.DoesNotExist: Video matching query does not exist.
[13/Nov/2020 20:00:50] "POST /api/django/summary/extract/ HTTP/1.0" 500 16227
[13/Nov/2020 20:01:48] "POST /api/django/summary/extract/ HTTP/1.0" 200 3
Internal Server Error: /api/django/summary/extract/
Traceback (most recent call last):
  File "/home/ubuntu/s03p31b108/backend/django/venv/lib/python3.6/site-packages/django/core/handlers/exception.py", line 34, in inner
    response = get_response(request)
  File "/home/ubuntu/s03p31b108/backend/django/venv/lib/python3.6/site-packages/django/core/handlers/base.py", line 115, in _get_response
    response = self.process_exception_by_middleware(e, request)
  File "/home/ubuntu/s03p31b108/backend/django/venv/lib/python3.6/site-packages/django/core/handlers/base.py", line 113, in _get_response
    response = wrapped_callback(request, *callback_args, **callback_kwargs)
  File "/home/ubuntu/s03p31b108/backend/django/venv/lib/python3.6/site-packages/django/views/decorators/csrf.py", line 54, in wrapped_view
    return view_func(*args, **kwargs)
  File "/home/ubuntu/s03p31b108/backend/django/venv/lib/python3.6/site-packages/django/views/generic/base.py", line 71, in view
    return self.dispatch(request, *args, **kwargs)
  File "/home/ubuntu/s03p31b108/backend/django/venv/lib/python3.6/site-packages/rest_framework/views.py", line 509, in dispatch
    response = self.handle_exception(exc)
  File "/home/ubuntu/s03p31b108/backend/django/venv/lib/python3.6/site-packages/rest_framework/views.py", line 469, in handle_exception
    self.raise_uncaught_exception(exc)
  File "/home/ubuntu/s03p31b108/backend/django/venv/lib/python3.6/site-packages/rest_framework/views.py", line 480, in raise_uncaught_exception
    raise exc
  File "/home/ubuntu/s03p31b108/backend/django/venv/lib/python3.6/site-packages/rest_framework/views.py", line 506, in dispatch
    response = handler(request, *args, **kwargs)
  File "/home/ubuntu/s03p31b108/backend/django/venv/lib/python3.6/site-packages/rest_framework/decorators.py", line 50, in handler
    return func(*args, **kwargs)
  File "/home/ubuntu/s03p31b108/backend/django/summary/views.py", line 137, in extract_image
    video = Video.objects.get(video_id=video_id)
  File "/home/ubuntu/s03p31b108/backend/django/venv/lib/python3.6/site-packages/django/db/models/manager.py", line 82, in manager_method
    return getattr(self.get_queryset(), name)(*args, **kwargs)
  File "/home/ubuntu/s03p31b108/backend/django/venv/lib/python3.6/site-packages/django/db/models/query.py", line 408, in get
    self.model._meta.object_name
summary.models.Video.DoesNotExist: Video matching query does not exist.
[13/Nov/2020 22:02:22] "POST /api/django/summary/extract/ HTTP/1.0" 500 16227
