Watching for file changes with StatReloader
[12/Nov/2020 19:45:04] "OPTIONS /api/django/summary/qna/ HTTP/1.0" 200 0
Bad Request: /api/django/summary/qna/
[12/Nov/2020 19:45:04] "POST /api/django/summary/qna/ HTTP/1.0" 400 68
[12/Nov/2020 19:45:17] "POST /api/django/summary/qna/ HTTP/1.0" 200 3
[12/Nov/2020 19:46:13] "OPTIONS /api/django/summary/qna/ HTTP/1.0" 200 0
Internal Server Error: /api/django/summary/qna/
Traceback (most recent call last):
  File "/home/ubuntu/s03p31b108/backend/django/venv/lib/python3.6/site-packages/nltk/corpus/util.py", line 83, in __load
    root = nltk.data.find("{}/{}".format(self.subdir, zip_name))
  File "/home/ubuntu/s03p31b108/backend/django/venv/lib/python3.6/site-packages/nltk/data.py", line 585, in find
    raise LookupError(resource_not_found)
LookupError: 
**********************************************************************
  Resource [93mbrown[0m not found.
  Please use the NLTK Downloader to obtain the resource:

  [31m>>> import nltk
  >>> nltk.download('brown')
  [0m
  For more information see: https://www.nltk.org/data.html

  Attempted to load [93mcorpora/brown.zip/brown/[0m

  Searched in:
    - '/home/ubuntu/nltk_data'
    - '/home/ubuntu/s03p31b108/backend/django/venv/nltk_data'
    - '/home/ubuntu/s03p31b108/backend/django/venv/share/nltk_data'
    - '/home/ubuntu/s03p31b108/backend/django/venv/lib/nltk_data'
    - '/usr/share/nltk_data'
    - '/usr/local/share/nltk_data'
    - '/usr/lib/nltk_data'
    - '/usr/local/lib/nltk_data'
**********************************************************************


During handling of the above exception, another exception occurred:

Traceback (most recent call last):
  File "/home/ubuntu/s03p31b108/backend/django/venv/lib/python3.6/site-packages/textblob/decorators.py", line 35, in decorated
    return func(*args, **kwargs)
  File "/home/ubuntu/s03p31b108/backend/django/venv/lib/python3.6/site-packages/textblob/en/np_extractors.py", line 109, in train
    train_data = nltk.corpus.brown.tagged_sents(categories='news')
  File "/home/ubuntu/s03p31b108/backend/django/venv/lib/python3.6/site-packages/nltk/corpus/util.py", line 120, in __getattr__
    self.__load()
  File "/home/ubuntu/s03p31b108/backend/django/venv/lib/python3.6/site-packages/nltk/corpus/util.py", line 85, in __load
    raise e
  File "/home/ubuntu/s03p31b108/backend/django/venv/lib/python3.6/site-packages/nltk/corpus/util.py", line 80, in __load
    root = nltk.data.find("{}/{}".format(self.subdir, self.__name))
  File "/home/ubuntu/s03p31b108/backend/django/venv/lib/python3.6/site-packages/nltk/data.py", line 585, in find
    raise LookupError(resource_not_found)
LookupError: 
**********************************************************************
  Resource [93mbrown[0m not found.
  Please use the NLTK Downloader to obtain the resource:

  [31m>>> import nltk
  >>> nltk.download('brown')
  [0m
  For more information see: https://www.nltk.org/data.html

  Attempted to load [93mcorpora/brown[0m

  Searched in:
    - '/home/ubuntu/nltk_data'
    - '/home/ubuntu/s03p31b108/backend/django/venv/nltk_data'
    - '/home/ubuntu/s03p31b108/backend/django/venv/share/nltk_data'
    - '/home/ubuntu/s03p31b108/backend/django/venv/lib/nltk_data'
    - '/usr/share/nltk_data'
    - '/usr/local/share/nltk_data'
    - '/usr/lib/nltk_data'
    - '/usr/local/lib/nltk_data'
**********************************************************************


During handling of the above exception, another exception occurred:

Traceback (most recent call last):
  File "/home/ubuntu/s03p31b108/backend/django/venv/lib/python3.6/site-packages/django/core/handlers/exception.py", line 34, in inner
    response = get_response(request)
  File "/home/ubuntu/s03p31b108/backend/django/venv/lib/python3.6/site-packages/django/core/handlers/base.py", line 115, in _get_response
    response = self.process_exception_by_middleware(e, request)
  File "/home/ubuntu/s03p31b108/backend/django/venv/lib/python3.6/site-packages/django/core/handlers/base.py", line 113, in _get_response
    response = wrapped_callback(request, *callback_args, **callback_kwargs)
  File "/home/ubuntu/s03p31b108/backend/django/venv/lib/python3.6/site-packages/django/views/decorators/csrf.py", line 54, in wrapped_view
    return view_func(*args, **kwargs)
  File "/home/ubuntu/s03p31b108/backend/django/venv/lib/python3.6/site-packages/django/views/generic/base.py", line 71, in view
    return self.dispatch(request, *args, **kwargs)
  File "/home/ubuntu/s03p31b108/backend/django/venv/lib/python3.6/site-packages/rest_framework/views.py", line 509, in dispatch
    response = self.handle_exception(exc)
  File "/home/ubuntu/s03p31b108/backend/django/venv/lib/python3.6/site-packages/rest_framework/views.py", line 469, in handle_exception
    self.raise_uncaught_exception(exc)
  File "/home/ubuntu/s03p31b108/backend/django/venv/lib/python3.6/site-packages/rest_framework/views.py", line 480, in raise_uncaught_exception
    raise exc
  File "/home/ubuntu/s03p31b108/backend/django/venv/lib/python3.6/site-packages/rest_framework/views.py", line 506, in dispatch
    response = handler(request, *args, **kwargs)
  File "/home/ubuntu/s03p31b108/backend/django/venv/lib/python3.6/site-packages/rest_framework/decorators.py", line 50, in handler
    return func(*args, **kwargs)
  File "/home/ubuntu/s03p31b108/backend/django/summary/views.py", line 176, in problem_create_list
    answers = eng.noun_phrases
  File "/home/ubuntu/s03p31b108/backend/django/venv/lib/python3.6/site-packages/textblob/decorators.py", line 24, in __get__
    value = obj.__dict__[self.func.__name__] = self.func(obj)
  File "/home/ubuntu/s03p31b108/backend/django/venv/lib/python3.6/site-packages/textblob/blob.py", line 468, in noun_phrases
    for phrase in self.np_extractor.extract(self.raw)
  File "/home/ubuntu/s03p31b108/backend/django/venv/lib/python3.6/site-packages/textblob/en/np_extractors.py", line 138, in extract
    self.train()
  File "/home/ubuntu/s03p31b108/backend/django/venv/lib/python3.6/site-packages/textblob/decorators.py", line 38, in decorated
    raise MissingCorpusError()
textblob.exceptions.MissingCorpusError: 
Looks like you are missing some required data for this feature.

To download the necessary data, simply run

    python -m textblob.download_corpora

or use the NLTK downloader to download the missing data: http://nltk.org/data.html
If this doesn't fix the problem, file an issue at https://github.com/sloria/TextBlob/issues.

[12/Nov/2020 19:46:15] "POST /api/django/summary/qna/ HTTP/1.0" 500 20638
Internal Server Error: /api/django/summary/qna/
Traceback (most recent call last):
  File "/home/ubuntu/s03p31b108/backend/django/venv/lib/python3.6/site-packages/nltk/corpus/util.py", line 83, in __load
    root = nltk.data.find("{}/{}".format(self.subdir, zip_name))
  File "/home/ubuntu/s03p31b108/backend/django/venv/lib/python3.6/site-packages/nltk/data.py", line 585, in find
    raise LookupError(resource_not_found)
LookupError: 
**********************************************************************
  Resource [93mbrown[0m not found.
  Please use the NLTK Downloader to obtain the resource:

  [31m>>> import nltk
  >>> nltk.download('brown')
  [0m
  For more information see: https://www.nltk.org/data.html

  Attempted to load [93mcorpora/brown.zip/brown/[0m

  Searched in:
    - '/home/ubuntu/nltk_data'
    - '/home/ubuntu/s03p31b108/backend/django/venv/nltk_data'
    - '/home/ubuntu/s03p31b108/backend/django/venv/share/nltk_data'
    - '/home/ubuntu/s03p31b108/backend/django/venv/lib/nltk_data'
    - '/usr/share/nltk_data'
    - '/usr/local/share/nltk_data'
    - '/usr/lib/nltk_data'
    - '/usr/local/lib/nltk_data'
**********************************************************************


During handling of the above exception, another exception occurred:

Traceback (most recent call last):
  File "/home/ubuntu/s03p31b108/backend/django/venv/lib/python3.6/site-packages/textblob/decorators.py", line 35, in decorated
    return func(*args, **kwargs)
  File "/home/ubuntu/s03p31b108/backend/django/venv/lib/python3.6/site-packages/textblob/en/np_extractors.py", line 109, in train
    train_data = nltk.corpus.brown.tagged_sents(categories='news')
  File "/home/ubuntu/s03p31b108/backend/django/venv/lib/python3.6/site-packages/nltk/corpus/util.py", line 120, in __getattr__
    self.__load()
  File "/home/ubuntu/s03p31b108/backend/django/venv/lib/python3.6/site-packages/nltk/corpus/util.py", line 85, in __load
    raise e
  File "/home/ubuntu/s03p31b108/backend/django/venv/lib/python3.6/site-packages/nltk/corpus/util.py", line 80, in __load
    root = nltk.data.find("{}/{}".format(self.subdir, self.__name))
  File "/home/ubuntu/s03p31b108/backend/django/venv/lib/python3.6/site-packages/nltk/data.py", line 585, in find
    raise LookupError(resource_not_found)
LookupError: 
**********************************************************************
  Resource [93mbrown[0m not found.
  Please use the NLTK Downloader to obtain the resource:

  [31m>>> import nltk
  >>> nltk.download('brown')
  [0m
  For more information see: https://www.nltk.org/data.html

  Attempted to load [93mcorpora/brown[0m

  Searched in:
    - '/home/ubuntu/nltk_data'
    - '/home/ubuntu/s03p31b108/backend/django/venv/nltk_data'
    - '/home/ubuntu/s03p31b108/backend/django/venv/share/nltk_data'
    - '/home/ubuntu/s03p31b108/backend/django/venv/lib/nltk_data'
    - '/usr/share/nltk_data'
    - '/usr/local/share/nltk_data'
    - '/usr/lib/nltk_data'
    - '/usr/local/lib/nltk_data'
**********************************************************************


During handling of the above exception, another exception occurred:

Traceback (most recent call last):
  File "/home/ubuntu/s03p31b108/backend/django/venv/lib/python3.6/site-packages/django/core/handlers/exception.py", line 34, in inner
    response = get_response(request)
  File "/home/ubuntu/s03p31b108/backend/django/venv/lib/python3.6/site-packages/django/core/handlers/base.py", line 115, in _get_response
    response = self.process_exception_by_middleware(e, request)
  File "/home/ubuntu/s03p31b108/backend/django/venv/lib/python3.6/site-packages/django/core/handlers/base.py", line 113, in _get_response
    response = wrapped_callback(request, *callback_args, **callback_kwargs)
  File "/home/ubuntu/s03p31b108/backend/django/venv/lib/python3.6/site-packages/django/views/decorators/csrf.py", line 54, in wrapped_view
    return view_func(*args, **kwargs)
  File "/home/ubuntu/s03p31b108/backend/django/venv/lib/python3.6/site-packages/django/views/generic/base.py", line 71, in view
    return self.dispatch(request, *args, **kwargs)
  File "/home/ubuntu/s03p31b108/backend/django/venv/lib/python3.6/site-packages/rest_framework/views.py", line 509, in dispatch
    response = self.handle_exception(exc)
  File "/home/ubuntu/s03p31b108/backend/django/venv/lib/python3.6/site-packages/rest_framework/views.py", line 469, in handle_exception
    self.raise_uncaught_exception(exc)
  File "/home/ubuntu/s03p31b108/backend/django/venv/lib/python3.6/site-packages/rest_framework/views.py", line 480, in raise_uncaught_exception
    raise exc
  File "/home/ubuntu/s03p31b108/backend/django/venv/lib/python3.6/site-packages/rest_framework/views.py", line 506, in dispatch
    response = handler(request, *args, **kwargs)
  File "/home/ubuntu/s03p31b108/backend/django/venv/lib/python3.6/site-packages/rest_framework/decorators.py", line 50, in handler
    return func(*args, **kwargs)
  File "/home/ubuntu/s03p31b108/backend/django/summary/views.py", line 176, in problem_create_list
    answers = eng.noun_phrases
  File "/home/ubuntu/s03p31b108/backend/django/venv/lib/python3.6/site-packages/textblob/decorators.py", line 24, in __get__
    value = obj.__dict__[self.func.__name__] = self.func(obj)
  File "/home/ubuntu/s03p31b108/backend/django/venv/lib/python3.6/site-packages/textblob/blob.py", line 468, in noun_phrases
    for phrase in self.np_extractor.extract(self.raw)
  File "/home/ubuntu/s03p31b108/backend/django/venv/lib/python3.6/site-packages/textblob/en/np_extractors.py", line 138, in extract
    self.train()
  File "/home/ubuntu/s03p31b108/backend/django/venv/lib/python3.6/site-packages/textblob/decorators.py", line 38, in decorated
    raise MissingCorpusError()
textblob.exceptions.MissingCorpusError: 
Looks like you are missing some required data for this feature.

To download the necessary data, simply run

    python -m textblob.download_corpora

or use the NLTK downloader to download the missing data: http://nltk.org/data.html
If this doesn't fix the problem, file an issue at https://github.com/sloria/TextBlob/issues.

[12/Nov/2020 19:48:03] "POST /api/django/summary/qna/ HTTP/1.0" 500 20164
Watching for file changes with StatReloader
[12/Nov/2020 19:58:12] "OPTIONS /api/django/summary/qna/ HTTP/1.0" 200 0
[12/Nov/2020 19:58:19] "POST /api/django/summary/qna/ HTTP/1.0" 200 1196
[12/Nov/2020 21:44:40] "OPTIONS /api/django/summary/extract_time/ HTTP/1.0" 200 0
[12/Nov/2020 21:44:43] "POST /api/django/summary/extract_time/ HTTP/1.0" 200 36
[12/Nov/2020 21:44:51] "POST /api/django/summary/extract_time/ HTTP/1.0" 200 36
ERROR: 6AnnvVrth4w: YouTube said: Unable to extract video data
[12/Nov/2020 21:44:58] "POST /api/django/summary/extract_time/ HTTP/1.0" 200 36
[12/Nov/2020 21:45:02] "POST /api/django/summary/extract_time/ HTTP/1.0" 200 36
