  File "manage.py", line 17
    ) from exc
         ^
SyntaxError: invalid syntax
Watching for file changes with StatReloader
Watching for file changes with StatReloader
[12/Nov/2020 11:17:38] "POST /api/django/summary/extract_time/ HTTP/1.0" 200 36
[12/Nov/2020 11:18:48] "POST /api/django/summary/extract_time/ HTTP/1.0" 200 36
ERROR: s9FHdj6jd_U: YouTube said: Unable to extract video data
[12/Nov/2020 11:19:29] "POST /api/django/summary/extract_time/ HTTP/1.0" 200 36
[12/Nov/2020 11:21:03] "POST /api/django/summary/extract_time/ HTTP/1.0" 200 36
[12/Nov/2020 11:21:10] "POST /api/django/summary/extract_time/ HTTP/1.0" 200 40
[12/Nov/2020 11:21:41] "POST /api/django/summary/extract_time/ HTTP/1.0" 200 40
ERROR: s9FHdj6jd_U: YouTube said: Unable to extract video data
[12/Nov/2020 11:45:50] "POST /api/django/summary/extract_time/ HTTP/1.0" 200 40
[12/Nov/2020 11:46:05] "POST /api/django/summary/extract_time/ HTTP/1.0" 200 40
[12/Nov/2020 11:46:21] "POST /api/django/summary/extract_time/ HTTP/1.0" 200 40
[12/Nov/2020 11:46:56] "POST /api/django/summary/extract_time/ HTTP/1.0" 200 40
[12/Nov/2020 11:48:26] "POST /api/django/summary/extract_time/ HTTP/1.0" 200 40
[12/Nov/2020 11:48:46] "POST /api/django/summary/extract_time/ HTTP/1.0" 200 40
[12/Nov/2020 11:49:21] "POST /api/django/summary/extract_time/ HTTP/1.0" 200 40
[12/Nov/2020 11:52:03] "POST /api/django/summary/extract_time/ HTTP/1.0" 200 40
ERROR: s9FHdj6jd_U: YouTube said: Unable to extract video data
[12/Nov/2020 12:50:05] "POST /api/django/summary/extract_time/ HTTP/1.0" 200 37
[12/Nov/2020 12:50:49] "POST /api/django/summary/extract_time/ HTTP/1.0" 200 37
[12/Nov/2020 12:50:50] "POST /api/django/summary/extract_time/ HTTP/1.0" 200 38
ERROR: s9FHdj6jd_U: YouTube said: Unable to extract video data
[12/Nov/2020 12:51:09] "POST /api/django/summary/extract_time/ HTTP/1.0" 200 37
[12/Nov/2020 12:51:15] "POST /api/django/summary/extract_time/ HTTP/1.0" 200 37
[12/Nov/2020 12:51:16] "POST /api/django/summary/extract_time/ HTTP/1.0" 200 38
[12/Nov/2020 12:51:29] "POST /api/django/summary/extract_time/ HTTP/1.0" 200 37
[12/Nov/2020 12:51:29] "POST /api/django/summary/extract_time/ HTTP/1.0" 200 38
[12/Nov/2020 12:51:58] "POST /api/django/summary/extract_time/ HTTP/1.0" 200 37
[12/Nov/2020 12:52:43] "POST /api/django/summary/extract_time/ HTTP/1.0" 200 36
[12/Nov/2020 12:52:43] "POST /api/django/summary/extract_time/ HTTP/1.0" 200 36
[12/Nov/2020 12:52:54] "POST /api/django/summary/extract_time/ HTTP/1.0" 200 36
[12/Nov/2020 13:04:46] "OPTIONS /api/django/summary/extract_time/ HTTP/1.0" 200 0
[12/Nov/2020 13:04:48] "POST /api/django/summary/extract_time/ HTTP/1.0" 200 36
[12/Nov/2020 13:06:05] "POST /api/django/summary/extract_time/ HTTP/1.0" 200 36
[12/Nov/2020 13:06:39] "POST /api/django/summary/extract_time/ HTTP/1.0" 200 36
[12/Nov/2020 13:10:44] "POST /api/django/summary/extract_time/ HTTP/1.0" 200 36
[12/Nov/2020 13:11:17] "POST /api/django/summary/extract_time/ HTTP/1.0" 200 36
[12/Nov/2020 13:16:15] "POST /api/django/summary/extract_time/ HTTP/1.0" 200 36
[12/Nov/2020 13:16:27] "POST /api/django/summary/extract_time/ HTTP/1.0" 200 36
[12/Nov/2020 13:47:02] "POST /api/django/summary/extract_time/ HTTP/1.0" 200 36
[12/Nov/2020 13:50:02] "POST /api/django/summary/extract_time/ HTTP/1.0" 200 36
[12/Nov/2020 13:54:55] "POST /api/django/summary/extract_time/ HTTP/1.0" 200 36
[12/Nov/2020 13:56:02] "POST /api/django/summary/extract_time/ HTTP/1.0" 200 36
[12/Nov/2020 13:56:21] "POST /api/django/summary/extract_time/ HTTP/1.0" 200 36
ERROR: s9FHdj6jd_U: YouTube said: Unable to extract video data
[12/Nov/2020 14:05:15] "POST /api/django/summary/extract_time/ HTTP/1.0" 200 36
[12/Nov/2020 14:06:58] "POST /api/django/summary/extract_time/ HTTP/1.0" 200 36
[12/Nov/2020 14:08:01] "POST /api/django/summary/extract_time/ HTTP/1.0" 200 36
[12/Nov/2020 14:08:44] "POST /api/django/summary/extract_time/ HTTP/1.0" 200 36
[12/Nov/2020 14:10:45] "POST /api/django/summary/extract_time/ HTTP/1.0" 200 36
[12/Nov/2020 14:10:57] "POST /api/django/summary/extract_time/ HTTP/1.0" 200 36
/home/ubuntu/s03p31b108/backend/django/summary/views.py changed, reloading.
Performing system checks...

System check identified no issues (0 silenced).
November 12, 2020 - 11:00:06
Django version 2.2, using settings 'API.settings'
Starting development server at http://127.0.0.1:8000/
Quit the server with CONTROL-C.
111
111
111
111
111
111
111
111
111
111
111
111
111
111
111
111
111
111
111
111
111
111
111
111
111
111
111
111
111
111
111
111
111
111
111
111
111
111
111
111
111
111
111
111
Watching for file changes with StatReloader
Performing system checks...

Traceback (most recent call last):
  File "manage.py", line 22, in <module>
    main()
  File "manage.py", line 18, in main
    execute_from_command_line(sys.argv)
  File "/home/ubuntu/s03p31b108/backend/django/venv/lib/python3.6/site-packages/django/core/management/__init__.py", line 381, in execute_from_command_line
    utility.execute()
  File "/home/ubuntu/s03p31b108/backend/django/venv/lib/python3.6/site-packages/django/core/management/__init__.py", line 375, in execute
    self.fetch_command(subcommand).run_from_argv(self.argv)
  File "/home/ubuntu/s03p31b108/backend/django/venv/lib/python3.6/site-packages/django/core/management/base.py", line 323, in run_from_argv
    self.execute(*args, **cmd_options)
  File "/home/ubuntu/s03p31b108/backend/django/venv/lib/python3.6/site-packages/django/core/management/commands/runserver.py", line 60, in execute
    super().execute(*args, **options)
  File "/home/ubuntu/s03p31b108/backend/django/venv/lib/python3.6/site-packages/django/core/management/base.py", line 364, in execute
    output = self.handle(*args, **options)
  File "/home/ubuntu/s03p31b108/backend/django/venv/lib/python3.6/site-packages/django/core/management/commands/runserver.py", line 95, in handle
    self.run(**options)
  File "/home/ubuntu/s03p31b108/backend/django/venv/lib/python3.6/site-packages/django/core/management/commands/runserver.py", line 102, in run
    autoreload.run_with_reloader(self.inner_run, **options)
  File "/home/ubuntu/s03p31b108/backend/django/venv/lib/python3.6/site-packages/django/utils/autoreload.py", line 579, in run_with_reloader
Exception in thread Thread-1:
Traceback (most recent call last):
  File "/usr/lib/python3.6/threading.py", line 916, in _bootstrap_inner
    self.run()
  File "/usr/lib/python3.6/threading.py", line 864, in run
    self._target(*self._args, **self._kwargs)
  File "/home/ubuntu/s03p31b108/backend/django/venv/lib/python3.6/site-packages/django/utils/autoreload.py", line 54, in wrapper
    fn(*args, **kwargs)
  File "/home/ubuntu/s03p31b108/backend/django/venv/lib/python3.6/site-packages/django/core/management/commands/runserver.py", line 117, in inner_run
    self.check(display_num_errors=True)
  File "/home/ubuntu/s03p31b108/backend/django/venv/lib/python3.6/site-packages/django/core/management/base.py", line 390, in check
    include_deployment_checks=include_deployment_checks,
  File "/home/ubuntu/s03p31b108/backend/django/venv/lib/python3.6/site-packages/django/core/management/base.py", line 377, in _run_checks
    return checks.run_checks(**kwargs)
  File "/home/ubuntu/s03p31b108/backend/django/venv/lib/python3.6/site-packages/django/core/checks/registry.py", line 72, in run_checks
    new_errors = check(app_configs=app_configs)
  File "/home/ubuntu/s03p31b108/backend/django/venv/lib/python3.6/site-packages/django/core/checks/urls.py", line 40, in check_url_namespaces_unique
    all_namespaces = _load_all_namespaces(resolver)
  File "/home/ubuntu/s03p31b108/backend/django/venv/lib/python3.6/site-packages/django/core/checks/urls.py", line 57, in _load_all_namespaces
    url_patterns = getattr(resolver, 'url_patterns', [])
  File "/home/ubuntu/s03p31b108/backend/django/venv/lib/python3.6/site-packages/django/utils/functional.py", line 80, in __get__
    res = instance.__dict__[self.name] = self.func(instance)
  File "/home/ubuntu/s03p31b108/backend/django/venv/lib/python3.6/site-packages/django/urls/resolvers.py", line 571, in url_patterns
    patterns = getattr(self.urlconf_module, "urlpatterns", self.urlconf_module)
  File "/home/ubuntu/s03p31b108/backend/django/venv/lib/python3.6/site-packages/django/utils/functional.py", line 80, in __get__
    res = instance.__dict__[self.name] = self.func(instance)
  File "/home/ubuntu/s03p31b108/backend/django/venv/lib/python3.6/site-packages/django/urls/resolvers.py", line 564, in urlconf_module
    return import_module(self.urlconf_name)
  File "/usr/lib/python3.6/importlib/__init__.py", line 126, in import_module
    return _bootstrap._gcd_import(name[level:], package, level)
  File "<frozen importlib._bootstrap>", line 994, in _gcd_import
  File "<frozen importlib._bootstrap>", line 971, in _find_and_load
  File "<frozen importlib._bootstrap>", line 955, in _find_and_load_unlocked
  File "<frozen importlib._bootstrap>", line 665, in _load_unlocked
  File "<frozen importlib._bootstrap_external>", line 678, in exec_module
  File "<frozen importlib._bootstrap>", line 219, in _call_with_frames_removed
  File "/home/ubuntu/s03p31b108/backend/django/API/urls.py", line 10, in <module>
    path('api/django/summary/', include('summary.urls')),
  File "/home/ubuntu/s03p31b108/backend/django/venv/lib/python3.6/site-packages/django/urls/conf.py", line 34, in include
    urlconf_module = import_module(urlconf_module)
  File "/usr/lib/python3.6/importlib/__init__.py", line 126, in import_module
    return _bootstrap._gcd_import(name[level:], package, level)
  File "<frozen importlib._bootstrap>", line 994, in _gcd_import
  File "<frozen importlib._bootstrap>", line 971, in _find_and_load
  File "<frozen importlib._bootstrap>", line 955, in _find_and_load_unlocked
  File "<frozen importlib._bootstrap>", line 665, in _load_unlocked
  File "<frozen importlib._bootstrap_external>", line 678, in exec_module
  File "<frozen importlib._bootstrap>", line 219, in _call_with_frames_removed
  File "/home/ubuntu/s03p31b108/backend/django/summary/urls.py", line 3, in <module>
    from . import views
  File "/home/ubuntu/s03p31b108/backend/django/summary/views.py", line 121
    <<<<<<< HEAD
               ^
IndentationError: expected an indented block

    start_django(reloader, main_func, *args, **kwargs)
  File "/home/ubuntu/s03p31b108/backend/django/venv/lib/python3.6/site-packages/django/utils/autoreload.py", line 564, in start_django
    reloader.run(django_main_thread)
  File "/home/ubuntu/s03p31b108/backend/django/venv/lib/python3.6/site-packages/django/utils/autoreload.py", line 272, in run
    get_resolver().urlconf_module
  File "/home/ubuntu/s03p31b108/backend/django/venv/lib/python3.6/site-packages/django/utils/functional.py", line 80, in __get__
    res = instance.__dict__[self.name] = self.func(instance)
  File "/home/ubuntu/s03p31b108/backend/django/venv/lib/python3.6/site-packages/django/urls/resolvers.py", line 564, in urlconf_module
    return import_module(self.urlconf_name)
  File "/usr/lib/python3.6/importlib/__init__.py", line 126, in import_module
    return _bootstrap._gcd_import(name[level:], package, level)
  File "<frozen importlib._bootstrap>", line 994, in _gcd_import
  File "<frozen importlib._bootstrap>", line 971, in _find_and_load
  File "<frozen importlib._bootstrap>", line 955, in _find_and_load_unlocked
  File "<frozen importlib._bootstrap>", line 665, in _load_unlocked
  File "<frozen importlib._bootstrap_external>", line 678, in exec_module
  File "<frozen importlib._bootstrap>", line 219, in _call_with_frames_removed
  File "/home/ubuntu/s03p31b108/backend/django/API/urls.py", line 10, in <module>
    path('api/django/summary/', include('summary.urls')),
  File "/home/ubuntu/s03p31b108/backend/django/venv/lib/python3.6/site-packages/django/urls/conf.py", line 34, in include
    urlconf_module = import_module(urlconf_module)
  File "/usr/lib/python3.6/importlib/__init__.py", line 126, in import_module
    return _bootstrap._gcd_import(name[level:], package, level)
  File "<frozen importlib._bootstrap>", line 994, in _gcd_import
  File "<frozen importlib._bootstrap>", line 971, in _find_and_load
  File "<frozen importlib._bootstrap>", line 955, in _find_and_load_unlocked
  File "<frozen importlib._bootstrap>", line 665, in _load_unlocked
  File "<frozen importlib._bootstrap_external>", line 678, in exec_module
  File "<frozen importlib._bootstrap>", line 219, in _call_with_frames_removed
  File "/home/ubuntu/s03p31b108/backend/django/summary/urls.py", line 3, in <module>
    from . import views
  File "/home/ubuntu/s03p31b108/backend/django/summary/views.py", line 121
    <<<<<<< HEAD
    ^
IndentationError: expected an indented block
